Workbook

Sheet Cómo leer
A1: SEMANA DEL 12 AL 18 DE OCTUBRE
A2: Qué cambió esta semana | B2: Guiones más largos (2 a 3 min en TikTok) y ajustados con los hallazgos de tu competencia: cada pieza trae LISTA DE 3, un DATO real (estudio o famoso) y un HACKEO para hacer contigo.
A3: TÍTULO DEL REEL | B3: Columna E, en morado grande: es el nombre de cada reel. Va como texto grande en pantalla los primeros 3 segundos y como portada.
A4: Guion por tiempos | B4: Todo lo que dices, con el segundo en que va cada parte. Las partes con ✂️ forman el corte de 60 a 90 s para Reels y Shorts.
A5: TU HISTORIA | B5: Va entre [corchetes]: es tu experiencia real, yo no la invento. Llénala antes de grabar o sáltala.
A6: Datos y famosos | B6: Todos son hechos públicos (Stanford 2023, Pennebaker, Skinner, Viktor Frankl, OMS, Gollwitzer, Jim Carrey, Beyoncé, Steve Jobs, Sara Blakely). Se dicen como dato, sin prometer resultados.
A7: Hora (Monterrey) | B7: De tus 40 TikToks: de 18 a 21 h rinden 6.3x tu mediana (7 videos) y de 10 a 13 h, 1.6x (5 videos). Es una señal, no una certeza.
A8: Hashtags | B8: 5 por pieza: #mabradiante + 2 del problema del día + 1 de tu nicho + #mty.
A9: Rendimiento esperado | B9: La meta contra tus propios números. No es una predicción.
A10: Celdas amarillas | B10: Las llenas tú: ¿Grabado?, ¿Publicado?, tus números reales y si coincidió con la simulación.
A11: Pestañas | B11: Calendario · Guion por partes · Mi semana · Podcast y YouTube · Querido Ex · Competencia (79 piezas) · Patrones de viralidad.

Sheet Calendario
A1: Día | B1: Fecha | C1: Hora (Monterrey) | D1: PIEZA | E1: TÍTULO DEL REEL (portada / texto en pantalla) | F1: PLATAFORMAS | G1: TEMA (problema) | H1: TIPO DE HOOK | I1: EMOCIÓN | J1: GUION COMPLETO POR TIEMPOS (✂️ = va en el corte de Reels) | K1: DURACIÓN | L1: FORMATO | M1: CTA: comenta… | N1: Producto | O1: COPY OUT (TikTok, Instagram y Facebook) | P1: Título YouTube Shorts | Q1: HASHTAGS | R1: RENDIMIENTO ESPERADO | S1: PATRÓN viral que usa | T1: Por qué en este orden y a esta hora | U1: Simulación (no predice vistas) | V1: Calificación | W1: Nota de la pieza | X1: ¿Grabado? | Y1: ¿Publicado? | Z1: Vistas reales | AA1: Likes reales | AB1: Comentarios reales | AC1: Compartidos reales | AD1: ¿Coincidió con la simulación?
A2: Lunes | B2: 2026-10-12 | C2: 12:30 | D2: LUN-1 | E2: 3 SEÑALES DE QUE TU MENTE RECHAZA EL DINERO | F2: TikTok · Instagram Reels · Facebook Reels · YouTube Shorts | G2: Dinero · programas de escasez | H2: G1 + lista · Romper creencia + 3 señales | I2: Identificación: «eso me pasa a mí» | J2: [0:00–0:11] GANCHO ✂️: "No es que no te alcance el dinero. Es que tu mente tiene 3 programas que lo sacan de tu vida, y casi nadie los ve." [0:11–0:21] GUARDAR Y COMPARTIR ✂️: "Guarda este video antes de que se te pierda y compártelo con alguien que siente que el dinero se le escapa de las manos." [0:21–0:41] DOLOR: "Te pagan y a la semana ya no hay. Te llega un dinero extra y justo aparece un gasto del mismo tamaño. Y empiezas a creer que el dinero no es para ti. No eres tú. Es un programa que se instaló antes de que pudieras elegirlo." [0:41–1:02] LISTA DE 3 ✂️: "Estas son las 3 señales: 1. Cuando te llega dinero sientes alivio… y luego culpa o miedo a perderlo. 2. Te cuesta cobrar lo que vale tu trabajo, y pedir más te da vergüenza. 3. En tu casa, hablar de dinero era sinónimo de pelea o de «no alcanza»." [1:02–1:25] DATO / AUTORIDAD: "Los investigadores Sendhil Mullainathan y Eldar Shafir lo explican en su libro «Escasez»: cuando la mente vive en carencia, le queda menos espacio para pensar y decidir. No es falta de inteligencia: es una mente ocupada sobreviviendo. Desde lo energético, es una frecuencia de «no alcanza» que se repite hasta que la ves." [1:25–1:45] TU HISTORIA: "[TU HISTORIA REAL, 15–20 s: la frase de dinero que más escuchaste de niña y cómo se repitió en tu vida]" [1:45–2:30] HACKEO (hazlo conmigo) ✂️: "Esta noche toma una hoja. Arriba escribe la frase de dinero que más escuchaste de niña. Abajo escribe su versión nueva. Por ejemplo: «no alcanza» se convierte en «el dinero llega y yo sé sostenerlo». Léela en voz alta 3 veces antes de dormir, durante 7 noches. Repite conmigo: el dinero llega y yo sé sostenerlo. El dinero llega y yo sé sostenerlo. El dinero llega y yo sé sostenerlo." [2:30–2:39] REVELACIÓN: "El dinero no se va porque seas mala con él. Se va porque tu cuerpo todavía no se siente seguro teniéndolo." [2:39–2:44] COMENTA ✂️: "Comenta SEÑALES y dime cuál de las 3 es la tuya." [2:44–2:50] CTA: "Sígueme: esta semana te traigo un hackeo para cada área de tu vida." | K2: TikTok ≈ 2:50 min Reels/Shorts ≈ 1:32 min | L2: Video vertical 9:16, cara a cámara. TikTok: versión completa. Reels y Shorts: corte con las partes ✂️. Pon el TÍTULO DEL REEL como texto grande en pantalla los primeros 3 s y como portada. | M2: SEÑALES | N2: Sin venta (conexión) | O2: ¿El dinero se te escapa apenas llega? 💸 Estas son las 3 señales de que tu mente lo está rechazando. Guarda este video y comenta SEÑALES 👇 #mabradiante #dinero #abundancia #hackeatumente #mty | P2: 3 señales de que tu mente rechaza el dinero #mabradiante #dinero #abundancia #hackeatumente #mty #shorts | Q2: #mabradiante #dinero #abundancia #hackeatumente #mty | R2: Meta: superar tu mediana de TikTok (11,850 vistas). Viral para ti: más de 17,775 (1.5x). Instagram, Facebook y YouTube: s/d, los medimos en la rutina semanal. | S2: P1 + P5 · Romper creencia + lista de señales | T2: Pieza 1 abre el tema del día con una creencia rota + lista de 3 señales (el combo que más rinde según tu competencia). Mediodía: tus TikToks de 10 a 13 h rinden 1.6x tu mediana (5 videos). | U2: Primera frase = gancho (G1, G2, G6 o G9), sin saludo: 2 Quita la culpa antes de enseñar: 1 Un dato de ciencia o un ejemplo real (hallazgo 2): 1 Algo para usar ya (hallazgo 1): 2 Pide guardar/compartir en los primeros 15 s: 1 Pide comentar una palabra: 1 Venta al final en 1 frase (o sin venta): 1 Vocabulario BNQ™, nada de la lista prohibida: 1 Total: 10/10 Lista de 3 (hallazgo 2): sí | V2: 10/10 | W2: Pieza de conexión (sin venta). Aplica H2: romper creencia + lista de 3 señales + estudio real.
A3: Lunes | B3: 2026-10-12 | C3: 18:30 | D3: LUN-2 | E3: DI ESTO CADA VEZ QUE PAGUES ALGO | F3: TikTok · Instagram Reels · Facebook Reels · YouTube Shorts | G3: Dinero · miedo al gastar o recibir | H3: G2 · Promesa práctica («Cuidado con este video…») | I3: Alivio: «algo que puedo hacer ya» | J3: [0:00–0:08] GANCHO ✂️: "Cuidado con este video porque vamos a cambiar la forma en que tu cuerpo recibe y suelta el dinero." [0:08–0:16] GUARDAR Y COMPARTIR ✂️: "Guárdalo antes de que se te pierda y compártelo con la amiga que siempre dice «no me alcanza»." [0:16–0:29] DOLOR: "Abres la app del banco y se te aprieta el estómago. Pagas algo y sientes que pierdes. Eso no es tacañería: es tu sistema nervioso asociando dinero con peligro." [0:29–0:46] LISTA DE 3 ✂️: "Lo vamos a hacer en 3 pasos: 1. Antes de pagar, pon la mano en el pecho y exhala largo. 2. Mira el dinero o la pantalla y di el decreto. 3. Sonríe al pagar, aunque al principio te cueste." [0:46–1:02] DATO / AUTORIDAD: "Tu cerebro aprende por repetición: cada vez que repites una sensación, esa conexión neuronal se fortalece. Por eso este ritual se hace 3 veces y durante 7 días. Lo espiritual lo llama decreto; la neurociencia, neuroplasticidad." [1:02–1:47] HACKEO (hazlo conmigo) ✂️: "Hagámoslo juntas ahora. Mano en el pecho. Inhala… y exhala largo. Ahora repite conmigo: gracias por llegar, te recibo con calma, te dejo ir sabiendo que regresas multiplicado. Otra vez: gracias por llegar, te recibo con calma, te dejo ir sabiendo que regresas multiplicado. Una más: gracias por llegar, te recibo con calma, te dejo ir sabiendo que regresas multiplicado. Tarro de miel, tarro de miel, tarro de miel." [1:47–1:55] REVELACIÓN: "No necesitas más dinero para estar en paz con él. Necesitas paz para que el dinero se quede." [1:55–1:58] COMENTA ✂️: "Cuando lo hagas, comenta HECHO ESTÁ." [1:58–2:01] CTA: "Guárdalo y hazlo 7 días seguidos." | K3: TikTok ≈ 2:01 min Reels/Shorts ≈ 1:21 min | L3: Video vertical 9:16, cara a cámara. TikTok: versión completa. Reels y Shorts: corte con las partes ✂️. Pon el TÍTULO DEL REEL como texto grande en pantalla los primeros 3 s y como portada. | M3: HECHO ESTÁ | N3: Sin venta (conexión) | O3: Di esto cada vez que pagues algo 💛 Un ritual de 30 segundos para que tu cuerpo deje de vivir el dinero como peligro. Guárdalo y comenta HECHO ESTÁ 👇 #mabradiante #dinero #abundancia #hackeatumente #mty | P3: Di esto cada vez que pagues algo #mabradiante #dinero #abundancia #hackeatumente #mty #shorts | Q3: #mabradiante #dinero #abundancia #hackeatumente #mty | R3: Meta: superar tu mediana de TikTok (11,850 vistas). Viral para ti: más de 17,775 (1.5x). Instagram, Facebook y YouTube: s/d, los medimos en la rutina semanal. | S3: P2 · Herramienta para usar ya | T3: Pieza 2 es la herramienta para usar ya: el patrón #1 de tu competencia (26x) y el de tus 4 videos más vistos. Va en tu mejor horario: de 18 a 21 h tus TikToks rinden 6.3x tu mediana (7 videos). | U3: Primera frase = gancho (G1, G2, G6 o G9), sin saludo: 2 Quita la culpa antes de enseñar: 0 Un dato de ciencia o un ejemplo real (hallazgo 2): 1 Algo para usar ya (hallazgo 1): 2 Pide guardar/compartir en los primeros 15 s: 1 Pide comentar una palabra: 1 Venta al final en 1 frase (o sin venta): 1 Vocabulario BNQ™, nada de la lista prohibida: 1 Total: 9/10 Lista de 3 (hallazgo 2): sí | V3: 9/10 | W3: Herramienta para usar ya (H1): mismo formato que tus 4 videos más vistos.
A4: Lunes | B4: 2026-10-12 | C4: 20:30 | D4: LUN-3 | E4: EL CHEQUE DE 10 MILLONES DE JIM CARREY | F4: TikTok · Instagram Reels · Facebook Reels · YouTube Shorts | G4: Dinero · visualizas y no llega | H4: G9 · Ejemplo famoso + lista | I4: Curiosidad: «¿cómo lo hizo?» | J4: [0:00–0:12] GANCHO ✂️: "Jim Carrey se escribió un cheque de 10 millones de dólares cuando todavía no tenía éxito. Y lo que hizo después es lo que casi nadie cuenta." [0:12–0:18] GUARDAR Y COMPARTIR ✂️: "Guárdalo y compártelo con alguien que ya hizo su vision board y sigue esperando." [0:18–0:26] DOLOR: "Tú también has escrito metas, has visualizado, has hecho rituales… y nada. Y empiezas a preguntarte qué te falta." [0:26–0:59] LISTA DE 3 ✂️: "Lo que hizo Carrey tiene 3 partes, y si te falta una, tu visualización se queda en sueño: 1. Una cifra y una fecha concretas: él puso 10 millones y Acción de Gracias de 1995. 2. Sentirlo en el cuerpo, no solo pensarlo: él lo cargaba en la cartera y lo veía cada día. 3. Actuar cada día como la persona que ya lo tiene: él mismo dice que no basta con visualizar y sentarse a esperar." [0:59–1:20] DATO / AUTORIDAD: "Carrey contó en entrevistas que a principios de los 90 se escribió ese cheque «por servicios de actuación prestados». Poco antes de esa fecha supo que le pagarían 10 millones por una película. Lo espiritual lo llama decretar; la psicología lo llama identidad: actúas según quien crees que eres." [1:20–1:40] TU HISTORIA: "[TU HISTORIA REAL, 15–20 s: una meta que se te dio cuando empezaste a actuar como si ya la tuvieras]" [1:40–2:21] HACKEO (hazlo conmigo) ✂️: "Hoy escribe tu propio cheque: tu nombre, una cifra realista para los próximos 12 meses y una fecha. Detrás escribe: ¿qué haría hoy la mujer que ya cobra esto? Y haz una de esas cosas hoy mismo. Repite conmigo: soy la mujer que ya lo recibe. Soy la mujer que ya lo recibe. Soy la mujer que ya lo recibe." [2:21–2:28] REVELACIÓN: "El cheque no trae el dinero. Te cambia a ti, y tú traes el dinero." [2:28–2:33] COMENTA ✂️: "Si quieres que te guíe, comenta ADN y te mando el link." [2:33–2:40] CTA: "En ADN Millonario trabajamos los programas de dinero que heredaste para activar tu frecuencia de abundancia." | K4: TikTok ≈ 2:40 min Reels/Shorts ≈ 1:37 min | L4: Video vertical 9:16, cara a cámara. TikTok: versión completa. Reels y Shorts: corte con las partes ✂️. Pon el TÍTULO DEL REEL como texto grande en pantalla los primeros 3 s y como portada. | M4: ADN | N4: ADN Millonario · $750 | O4: Jim Carrey se escribió un cheque de 10 millones antes de tener éxito 🧾 Te cuento las 3 partes que casi nadie hace. Comenta ADN y te mando el link 👇 #mabradiante #dinero #abundancia #hackeatumente #mty | P4: El cheque de 10 millones de Jim Carrey #mabradiante #dinero #abundancia #hackeatumente #mty #shorts | Q4: #mabradiante #dinero #abundancia #hackeatumente #mty | R4: Meta: superar tu mediana de TikTok (11,850 vistas). Viral para ti: más de 17,775 (1.5x). Instagram, Facebook y YouTube: s/d, los medimos en la rutina semanal. | S4: P7 + P5 · Famoso + lista de 3 | T4: Pieza 3 vende, apoyada en un famoso o estudio real (7.6x) + lista. Va al final del día, cuando ya calentaste el tema. Sigue en tu mejor franja. | U4: Primera frase = gancho (G1, G2, G6 o G9), sin saludo: 2 Quita la culpa antes de enseñar: 0 Un dato de ciencia o un ejemplo real (hallazgo 2): 1 Algo para usar ya (hallazgo 1): 2 Pide guardar/compartir en los primeros 15 s: 1 Pide comentar una palabra: 1 Venta al final en 1 frase (o sin venta): 1 Vocabulario BNQ™, nada de la lista prohibida: 1 Total: 9/10 Lista de 3 (hallazgo 2): sí | V4: 9/10 | W4: Pieza de venta del día (1 de 3). Aplica H2: famoso real + lista de 3.
A5: Martes | B5: 2026-10-13 | C5: 12:30 | D5: MAR-1 | E5: 3 SEÑALES DE ANSIEDAD QUE CREES QUE SON TU PERSONALIDAD | F5: TikTok · Instagram Reels · Facebook Reels · YouTube Shorts | G5: Ansiedad · se confunde con personalidad | H5: G1 + lista · Romper creencia + 3 señales | I5: Identificación: «eso me pasa a mí» | J5: [0:00–0:08] GANCHO ✂️: "No eres intensa ni exagerada. Hay 3 señales de ansiedad que la mayoría confunde con su forma de ser." [0:08–0:13] GUARDAR Y COMPARTIR ✂️: "Guárdalo y compártelo con alguien a quien siempre le dicen «relájate»." [0:13–0:26] DOLOR: "Por fuera estás bien, por dentro vas corriendo. Te dicen «relájate» y te dan ganas de llorar. No es que seas así. Es que tu cuerpo aprendió a vivir en alerta." [0:26–0:41] LISTA DE 3 ✂️: "Estas son las 3 señales: 1. Necesitas tener todo bajo control, y un cambio de planes te desarma. 2. Imaginas la peor versión de todo «para estar preparada». 3. Te cuesta descansar sin sentir culpa." [0:41–1:02] DATO / AUTORIDAD: "La ciencia lo explica así: cuando el cerebro se acostumbra a estar en alerta, la amígdala, tu detector de peligro, se activa con más facilidad, y el cuerpo vive como si algo malo estuviera por pasar. Las tradiciones contemplativas lo llaman una mente que no está en el presente." [1:02–1:22] TU HISTORIA: "[TU HISTORIA REAL, 15–20 s: cómo se veía tu ansiedad con TDAH antes de aprender a dirigir tu mente]" [1:22–2:00] HACKEO (hazlo conmigo) ✂️: "Cuando notes una de estas 3 señales, ponle nombre en voz baja: «esto es mi alarma, no la realidad». Luego pregúntate: ¿qué es lo que sí está pasando ahora mismo? Repite conmigo: esto es mi alarma, no la realidad. Esto es mi alarma, no la realidad. Esto es mi alarma, no la realidad." [2:00–2:06] REVELACIÓN: "Tú no eres ansiosa. Tienes una alarma que nadie te enseñó a apagar." [2:06–2:11] COMENTA ✂️: "Comenta ALARMA y dime cuál de las 3 te pasa más." [2:11–2:14] CTA: "Sígueme para más hackeos para tu mente." | K5: TikTok ≈ 2:14 min Reels/Shorts ≈ 1:11 min | L5: Video vertical 9:16, cara a cámara. TikTok: versión completa. Reels y Shorts: corte con las partes ✂️. Pon el TÍTULO DEL REEL como texto grande en pantalla los primeros 3 s y como portada. | M5: ALARMA | N5: Sin venta (conexión) | O5: ¿Y si no eres «intensa», sino que tu cuerpo vive en alerta? 🚨 3 señales de ansiedad que confundes con tu personalidad. Comenta ALARMA 👇 #mabradiante #ansiedad #calmamental #hackeatumente #mty | P5: 3 señales de ansiedad que confundes con tu personalidad #mabradiante #ansiedad #calmamental #hackeatumente #mty #shorts | Q5: #mabradiante #ansiedad #calmamental #hackeatumente #mty | R5: Meta: superar tu mediana de TikTok (11,850 vistas). Viral para ti: más de 17,775 (1.5x). Instagram, Facebook y YouTube: s/d, los medimos en la rutina semanal. | S5: P1 + P5 · Romper creencia + lista de señales | T5: Pieza 1 abre el tema del día con una creencia rota + lista de 3 señales (el combo que más rinde según tu competencia). Mediodía: tus TikToks de 10 a 13 h rinden 1.6x tu mediana (5 videos). | U5: Primera frase = gancho (G1, G2, G6 o G9), sin saludo: 2 Quita la culpa antes de enseñar: 1 Un dato de ciencia o un ejemplo real (hallazgo 2): 1 Algo para usar ya (hallazgo 1): 2 Pide guardar/compartir en los primeros 15 s: 1 Pide comentar una palabra: 1 Venta al final en 1 frase (o sin venta): 1 Vocabulario BNQ™, nada de la lista prohibida: 1 Total: 10/10 Lista de 3 (hallazgo 2): sí | V5: 10/10 | W5: Sin venta. Sin diagnósticos: si la ansiedad es fuerte o constante, recomendar ayuda profesional.
A6: Martes | B6: 2026-10-13 | C6: 18:30 | D6: MAR-2 | E6: EL SUSPIRO QUE BAJA LA ANSIEDAD EN 1 MINUTO | F6: TikTok · Instagram Reels · Facebook Reels · YouTube Shorts | G6: Ansiedad · ataque en el cuerpo | H6: G2 · Promesa práctica | I6: Alivio: «algo que puedo hacer ya» | J6: [0:00–0:07] GANCHO ✂️: "Haz esto conmigo ahora mismo y siente cómo baja la ansiedad en menos de un minuto." [0:07–0:14] GUARDAR Y COMPARTIR ✂️: "Guárdalo para cuando lo necesites y compártelo con alguien que hoy trae el pecho apretado." [0:14–0:24] DOLOR: "Ese nudo en el pecho, el corazón rápido, la mente que no para. Y todos te dicen «respira»… pero nadie te dice cómo." [0:24–0:37] LISTA DE 3 ✂️: "Se llama suspiro cíclico y son 3 pasos: 1. Inhala por la nariz. 2. Encima, una segunda inhalación cortita, hasta llenarte. 3. Exhala largo y lento por la boca." [0:37–1:00] DATO / AUTORIDAD: "En 2023, un estudio de la Universidad de Stanford, publicado en Cell Reports Medicine, comparó varias técnicas de respiración. Las personas que hicieron este suspiro 5 minutos al día mejoraron más su estado de ánimo que las que hicieron meditación de atención. La exhalación larga le avisa a tu cuerpo que no hay peligro." [1:00–1:36] HACKEO (hazlo conmigo) ✂️: "Hagámoslo juntas. Inhala por la nariz… otra inhalación cortita encima… y exhala largo por la boca. Otra vez: inhala… otra cortita… exhala largo. Una vez más: inhala… cortita… y suelta todo. Ahora repite conmigo: estoy a salvo. Estoy a salvo. Estoy a salvo. Hielo azul, hielo azul, hielo azul." [1:36–1:43] REVELACIÓN: "Tu respiración es el control remoto de tu sistema nervioso, y lo traes contigo a todas partes." [1:43–1:46] COMENTA ✂️: "Si sentiste la diferencia, comenta CALMA." [1:46–1:50] CTA: "Guárdalo y hazlo 5 minutos al día esta semana." | K6: TikTok ≈ 1:50 min Reels/Shorts ≈ 1:06 min | L6: Video vertical 9:16, cara a cámara. TikTok: versión completa. Reels y Shorts: corte con las partes ✂️. Pon el TÍTULO DEL REEL como texto grande en pantalla los primeros 3 s y como portada. | M6: CALMA | N6: Sin venta (conexión) | O6: El suspiro que baja la ansiedad en 1 minuto 🫁 Lo estudió Stanford. Hazlo conmigo, guárdalo y comenta CALMA 👇 #mabradiante #ansiedad #calmamental #hackeatumente #mty | P6: El suspiro que baja la ansiedad en 1 minuto #mabradiante #ansiedad #calmamental #hackeatumente #mty #shorts | Q6: #mabradiante #ansiedad #calmamental #hackeatumente #mty | R6: Meta: superar tu mediana de TikTok (11,850 vistas). Viral para ti: más de 17,775 (1.5x). Instagram, Facebook y YouTube: s/d, los medimos en la rutina semanal. | S6: P2 + P7 · Herramienta + estudio | T6: Pieza 2 es la herramienta para usar ya: el patrón #1 de tu competencia (26x) y el de tus 4 videos más vistos. Va en tu mejor horario: de 18 a 21 h tus TikToks rinden 6.3x tu mediana (7 videos). | U6: Primera frase = gancho (G1, G2, G6 o G9), sin saludo: 2 Quita la culpa antes de enseñar: 0 Un dato de ciencia o un ejemplo real (hallazgo 2): 1 Algo para usar ya (hallazgo 1): 2 Pide guardar/compartir en los primeros 15 s: 1 Pide comentar una palabra: 1 Venta al final en 1 frase (o sin venta): 1 Vocabulario BNQ™, nada de la lista prohibida: 1 Total: 9/10 Lista de 3 (hallazgo 2): sí | V6: 9/10 | W6: Herramienta para usar ya (H1) + estudio real (H2). Sin promesas de curación.
A7: Martes | B7: 2026-10-13 | C7: 20:30 | D7: MAR-3 | E7: 15 MINUTOS DE ESCRITURA QUE CALMAN TU MENTE | F7: TikTok · Instagram Reels · Facebook Reels · YouTube Shorts | G7: Ansiedad · mente que no apaga en la noche | H7: G6 · Autoridad científica + lista | I7: Curiosidad: «¿cómo funciona?» | J7: [0:00–0:10] GANCHO ✂️: "Un psicólogo de Texas descubrió que escribir 15 minutos lo que sientes puede bajar tu carga mental. Y casi nadie lo usa." [0:10–0:16] GUARDAR Y COMPARTIR ✂️: "Guárdalo y compártelo con alguien que se acuesta y su mente se prende." [0:16–0:26] DOLOR: "Te acuestas, apagas la luz… y tu mente empieza a repasar todo lo que dijiste, lo que falta y lo que podría salir mal." [0:26–0:40] LISTA DE 3 ✂️: "Tu mente no suelta por 3 errores muy comunes: 1. Intentas no pensar, y piensas más. 2. Te llevas los pendientes a la cama. 3. Te callas lo que sientes para no molestar." [0:40–1:02] DATO / AUTORIDAD: "James Pennebaker, de la Universidad de Texas, estudió la «escritura expresiva»: personas que escribieron de 15 a 20 minutos sobre lo que sentían, durante unos días, reportaron sentirse mejor que las que escribieron de temas neutros. Desde lo energético: lo que no se expresa se queda dando vueltas en tu campo." [1:02–1:22] TU HISTORIA: "[TU HISTORIA REAL, 15–20 s: qué hacías tú en las noches cuando tu mente no te dejaba dormir]" [1:22–2:06] HACKEO (hazlo conmigo) ✂️: "Hoy, antes de dormir: 10 minutos escribiendo sin parar lo que sientes, no lo que tienes que hacer. No corrijas nada. Cuando termines, cierra la libreta y di: lo solté en el papel, ya no lo cargo en el cuerpo. Repite conmigo: lo solté en el papel, ya no lo cargo en el cuerpo. Lo solté en el papel, ya no lo cargo en el cuerpo." [2:06–2:13] REVELACIÓN: "Lo que no se expresa se queda dando vueltas. Lo que escribes deja de cargarte." [2:13–2:19] COMENTA ✂️: "Si tu mente no te deja dormir, comenta DORMIR y te mando el link." [2:19–2:27] CTA: "En Querida Ansiedad te doy la auditoría mental y los audios para bajarle la velocidad a tu mente." | K7: TikTok ≈ 2:27 min Reels/Shorts ≈ 1:20 min | L7: Video vertical 9:16, cara a cámara. TikTok: versión completa. Reels y Shorts: corte con las partes ✂️. Pon el TÍTULO DEL REEL como texto grande en pantalla los primeros 3 s y como portada. | M7: DORMIR | N7: Querida Ansiedad · $399 | O7: 15 minutos de escritura que calman tu mente ✍️ Lo estudió la Universidad de Texas. Te digo cómo hacerlo hoy. Comenta DORMIR y te mando el link 👇 #mabradiante #ansiedad #calmamental #hackeatumente #mty | P7: 15 minutos de escritura que calman tu mente #mabradiante #ansiedad #calmamental #hackeatumente #mty #shorts | Q7: #mabradiante #ansiedad #calmamental #hackeatumente #mty | R7: Meta: superar tu mediana de TikTok (11,850 vistas). Viral para ti: más de 17,775 (1.5x). Instagram, Facebook y YouTube: s/d, los medimos en la rutina semanal. | S7: P7 + P5 · Estudio + lista de 3 | T7: Pieza 3 vende, apoyada en un famoso o estudio real (7.6x) + lista. Va al final del día, cuando ya calentaste el tema. Sigue en tu mejor franja. | U7: Primera frase = gancho (G1, G2, G6 o G9), sin saludo: 2 Quita la culpa antes de enseñar: 0 Un dato de ciencia o un ejemplo real (hallazgo 2): 1 Algo para usar ya (hallazgo 1): 2 Pide guardar/compartir en los primeros 15 s: 1 Pide comentar una palabra: 1 Venta al final en 1 frase (o sin venta): 1 Vocabulario BNQ™, nada de la lista prohibida: 1 Total: 9/10 Lista de 3 (hallazgo 2): sí | V7: 9/10 | W7: Pieza de venta del día (1 de 3). Sin promesas de salud.
A8: Miércoles | B8: 2026-10-14 | C8: 12:30 | D8: MIÉ-1 | E8: 3 SEÑALES DE QUE NO ES AMOR, ES ENGANCHE | F8: TikTok · Instagram Reels · Facebook Reels · YouTube Shorts | G8: Relaciones · enganche que parece amor | H8: G1 + lista · Romper creencia + 3 señales | I8: Identificación: «eso me pasa a mí» | J8: [0:00–0:08] GANCHO ✂️: "No es que lo ames demasiado. Es que tu cerebro está enganchado, y hay 3 señales que lo delatan." [0:08–0:14] GUARDAR Y COMPARTIR ✂️: "Guárdalo y compártelo con esa amiga que siempre vuelve con la misma persona." [0:14–0:24] DOLOR: "Revisas si se conectó. Ves sus historias aunque te duelan. Te prometes no escribirle… y le escribes. No estás loca. Estás enganchada." [0:24–0:44] LISTA DE 3 ✂️: "Estas son las 3 señales: 1. Te sientes peor cuando lo ves, pero no puedes dejar de buscarlo. 2. Un mensaje suyo te sube al cielo y su silencio te tira al piso. 3. Ya sabes que no te hace bien… y aun así lo justificas." [0:44–1:07] DATO / AUTORIDAD: "El psicólogo B. F. Skinner observó que cuando una recompensa llega a veces sí y a veces no, la conducta se vuelve más difícil de soltar. Es lo mismo que pasa con las máquinas tragamonedas. Por eso una relación intermitente engancha más que una estable. En lo energético, es un cordón que sigue abierto." [1:07–1:27] TU HISTORIA: "[TU HISTORIA REAL, 15–20 s: una relación en la que confundiste intensidad con amor]" [1:27–2:06] HACKEO (hazlo conmigo) ✂️: "Esta semana, cada vez que quieras revisar su perfil, cuenta hasta 10 y di en voz baja: esto es enganche, no amor; mi atención es mía. Repite conmigo: esto es enganche, no amor; mi atención es mía. Esto es enganche, no amor; mi atención es mía. Esto es enganche, no amor; mi atención es mía." [2:06–2:13] REVELACIÓN: "El enganche se siente como amor porque es intenso. El amor sano se siente como paz." [2:13–2:17] COMENTA ✂️: "Comenta ENGANCHE si te pasó o te está pasando." [2:17–2:20] CTA: "Sígueme: estoy preparando algo para ayudarte a soltar." | K8: TikTok ≈ 2:20 min Reels/Shorts ≈ 1:17 min | L8: Video vertical 9:16, cara a cámara. TikTok: versión completa. Reels y Shorts: corte con las partes ✂️. Pon el TÍTULO DEL REEL como texto grande en pantalla los primeros 3 s y como portada. | M8: ENGANCHE | N8: Sin venta (conexión) | O8: ¿Es amor o es enganche? 💔 3 señales que lo delatan (y por qué una relación intermitente engancha más). Comenta ENGANCHE 👇 #mabradiante #relaciones #amorpropio #dependenciaemocional #mty | P8: 3 señales de que no es amor, es enganche #mabradiante #relaciones #amorpropio #dependenciaemocional #mty #shorts | Q8: #mabradiante #relaciones #amorpropio #dependenciaemocional #mty | R8: Meta: superar tu mediana de TikTok (11,850 vistas). Viral para ti: más de 17,775 (1.5x). Instagram, Facebook y YouTube: s/d, los medimos en la rutina semanal. | S8: P1 + P5 + P7 · Creencia + lista + estudio | T8: Pieza 1 abre el tema del día con una creencia rota + lista de 3 señales (el combo que más rinde según tu competencia). Mediodía: tus TikToks de 10 a 13 h rinden 1.6x tu mediana (5 videos). | U8: Primera frase = gancho (G1, G2, G6 o G9), sin saludo: 2 Quita la culpa antes de enseñar: 1 Un dato de ciencia o un ejemplo real (hallazgo 2): 1 Algo para usar ya (hallazgo 1): 2 Pide guardar/compartir en los primeros 15 s: 1 Pide comentar una palabra: 1 Venta al final en 1 frase (o sin venta): 1 Vocabulario BNQ™, nada de la lista prohibida: 1 Total: 10/10 Lista de 3 (hallazgo 2): sí | V8: 10/10 | W8: Sin venta. Siembra el tema de Querido Ex sin venderlo todavía. Relaciones es el tema con más virales (H3).
A9: Miércoles | B9: 2026-10-14 | C9: 18:30 | D9: MIÉ-2 | E9: CORTA EL CORDÓN CON ESTE DECRETO | F9: TikTok · Instagram Reels · Facebook Reels · YouTube Shorts | G9: Relaciones · no puedo dejar de pensarle | H9: G2 · Promesa práctica («Cuidado con este video…») | I9: Alivio: «algo que puedo hacer ya» | J9: [0:00–0:07] GANCHO ✂️: "Cuidado con este video si no puedes dejar de pensar en alguien que ya se fue." [0:07–0:14] GUARDAR Y COMPARTIR ✂️: "Guárdalo para la noche en que más lo necesites y compártelo con quien está soltando a alguien." [0:14–0:24] DOLOR: "Ya terminó, pero sigues sintiéndolo. Piensas en él justo cuando él publica algo. Es como si hubiera un cable que nunca se desconectó." [0:24–0:38] LISTA DE 3 ✂️: "El ritual tiene 3 pasos: 1. Cierra los ojos e imagínalo frente a ti. 2. Observa el cordón de luz que los une. 3. Córtalo con amor, sin rabia, con el decreto." [0:38–0:55] DATO / AUTORIDAD: "En muchas tradiciones espirituales se habla de cordones energéticos: los lazos que quedan después de una relación. No es ciencia, es un ritual, y los rituales le dan al cuerpo un cierre que la mente sola no encuentra." [0:55–1:41] HACKEO (hazlo conmigo) ✂️: "Hagámoslo ahora. Cierra los ojos. Imagínalo frente a ti. Mira el cordón que los une. Ahora, en tu mano aparece una espada de luz. Repite conmigo: te devuelvo lo que es tuyo, recupero lo que es mío. Te devuelvo lo que es tuyo, recupero lo que es mío. Te devuelvo lo que es tuyo, recupero lo que es mío. Espada de luz, espada de luz, espada de luz. Corta. Respira. Hecho está." [1:41–1:45] REVELACIÓN: "Soltar no es olvidarlo. Es dejar de darle tu energía." [1:45–1:47] COMENTA ✂️: "Cuando lo hagas, comenta LIBRE." [1:47–1:49] CTA: "Guárdalo para cuando lo necesites." | K9: TikTok ≈ 1:49 min Reels/Shorts ≈ 1:16 min | L9: Video vertical 9:16, cara a cámara. TikTok: versión completa. Reels y Shorts: corte con las partes ✂️. Pon el TÍTULO DEL REEL como texto grande en pantalla los primeros 3 s y como portada. | M9: LIBRE | N9: Sin venta (conexión) | O9: Corta el cordón con este decreto ✂️✨ Para cuando no puedes dejar de pensar en alguien que ya se fue. Guárdalo y comenta LIBRE 👇 #mabradiante #relaciones #amorpropio #dependenciaemocional #mty | P9: Corta el cordón con este decreto #mabradiante #relaciones #amorpropio #dependenciaemocional #mty #shorts | Q9: #mabradiante #relaciones #amorpropio #dependenciaemocional #mty | R9: Meta: superar tu mediana de TikTok (11,850 vistas). Viral para ti: más de 17,775 (1.5x). Instagram, Facebook y YouTube: s/d, los medimos en la rutina semanal. | S9: P2 · Herramienta para usar ya | T9: Pieza 2 es la herramienta para usar ya: el patrón #1 de tu competencia (26x) y el de tus 4 videos más vistos. Va en tu mejor horario: de 18 a 21 h tus TikToks rinden 6.3x tu mediana (7 videos). | U9: Primera frase = gancho (G1, G2, G6 o G9), sin saludo: 2 Quita la culpa antes de enseñar: 0 Un dato de ciencia o un ejemplo real (hallazgo 2): 1 Algo para usar ya (hallazgo 1): 2 Pide guardar/compartir en los primeros 15 s: 1 Pide comentar una palabra: 1 Venta al final en 1 frase (o sin venta): 1 Vocabulario BNQ™, nada de la lista prohibida: 1 Total: 9/10 Lista de 3 (hallazgo 2): sí | V9: 9/10 | W9: Herramienta para usar ya (H1). Es un adelanto del Día 3 de Querido Ex (siembra, sin venta).
A10: Miércoles | B10: 2026-10-14 | C10: 20:30 | D10: MIÉ-3 | E10: BEYONCÉ TENÍA UN ALTER EGO: SASHA FIERCE | F10: TikTok · Instagram Reels · Facebook Reels · YouTube Shorts | G10: Relaciones · te conformas, ruegas | H10: G9 · Ejemplo famoso + estudio + lista | I10: Inspiración: «yo también puedo» | J10: [0:00–0:12] GANCHO ✂️: "Beyoncé contó que era tímida en el escenario hasta que creó a Sasha Fierce. Y eso tiene todo que ver con por qué te conformas en el amor." [0:12–0:18] GUARDAR Y COMPARTIR ✂️: "Guárdalo y compártelo con la amiga que siempre explica de más lo que necesita." [0:18–0:25] DOLOR: "Sabes lo que mereces, pero cuando estás frente a esa persona te haces chiquita. Ruegas, explicas, esperas." [0:25–0:43] LISTA DE 3 ✂️: "Tu alter ego en el amor hace 3 cosas que tú todavía no: 1. No explica de más lo que necesita. 2. Se va cuando algo no le hace bien, sin pedir permiso. 3. Elige con calma, no con hambre de cariño." [0:43–1:05] DATO / AUTORIDAD: "Hay un estudio de 2017 con niños, en la revista Child Development, que encontró algo curioso: los que se imaginaban como un personaje, por ejemplo Batman, perseveraban más en una tarea aburrida. Le llamaron el «efecto Batman». Tomar distancia de ti misma a través de un personaje te da fuerza." [1:05–1:25] TU HISTORIA: "[TU HISTORIA REAL, 15–20 s: una vez que te hiciste chiquita frente a alguien y qué habría hecho tu versión fuerte]" [1:25–2:03] HACKEO (hazlo conmigo) ✂️: "Ponle nombre a tu versión que ya no ruega. Hoy, antes de responder un mensaje, pregúntate: ¿qué haría ella? Y responde desde ahí. Repite conmigo: yo elijo desde mi valor, no desde mi miedo. Yo elijo desde mi valor, no desde mi miedo. Yo elijo desde mi valor, no desde mi miedo." [2:03–2:10] REVELACIÓN: "No necesitas convertirte en otra persona. Necesitas permiso para ser la versión que ya existe en ti." [2:10–2:16] COMENTA ✂️: "Si quieres crear la tuya, comenta ALTER EGO y te mando el link." [2:16–2:23] CTA: "En Crea y Activa tu Alter Ego te guío paso a paso para instalar esa identidad." | K10: TikTok ≈ 2:23 min Reels/Shorts ≈ 1:20 min | L10: Video vertical 9:16, cara a cámara. TikTok: versión completa. Reels y Shorts: corte con las partes ✂️. Pon el TÍTULO DEL REEL como texto grande en pantalla los primeros 3 s y como portada. | M10: ALTER EGO | N10: Crea y Activa tu Alter Ego · $599 | O10: Beyoncé tenía un alter ego: Sasha Fierce 🔥 ¿Y tú? 3 cosas que haría tu versión fuerte en el amor. Comenta ALTER EGO y te mando el link 👇 #mabradiante #relaciones #amorpropio #dependenciaemocional #mty | P10: Beyoncé tenía un alter ego: Sasha Fierce #mabradiante #relaciones #amorpropio #dependenciaemocional #mty #shorts | Q10: #mabradiante #relaciones #amorpropio #dependenciaemocional #mty | R10: Meta: superar tu mediana de TikTok (11,850 vistas). Viral para ti: más de 17,775 (1.5x). Instagram, Facebook y YouTube: s/d, los medimos en la rutina semanal. | S10: P7 + P5 · Famoso + estudio + lista de 3 | T10: Pieza 3 vende, apoyada en un famoso o estudio real (7.6x) + lista. Va al final del día, cuando ya calentaste el tema. Sigue en tu mejor franja. | U10: Primera frase = gancho (G1, G2, G6 o G9), sin saludo: 2 Quita la culpa antes de enseñar: 0 Un dato de ciencia o un ejemplo real (hallazgo 2): 1 Algo para usar ya (hallazgo 1): 2 Pide guardar/compartir en los primeros 15 s: 1 Pide comentar una palabra: 1 Venta al final en 1 frase (o sin venta): 1 Vocabulario BNQ™, nada de la lista prohibida: 1 Total: 9/10 Lista de 3 (hallazgo 2): sí | V10: 9/10 | W10: Pieza de venta del día (1 de 3). Querido Ex todavía no se vende: Alter Ego cubre Relaciones.
A11: Jueves | B11: 2026-10-15 | C11: 12:30 | D11: JUE-1 | E11: 3 SEÑALES DE QUE ESTÁS DESPERTANDO (Y POR QUÉ DUELE) | F11: TikTok · Instagram Reels · Facebook Reels · YouTube Shorts | G11: Vacío · nada me llena | H11: G1 + lista · Reencuadre + 3 señales | I11: Identificación: «eso me pasa a mí» | J11: [0:00–0:07] GANCHO ✂️: "No es que estés perdida. Puede que estés despertando, y hay 3 señales que lo delatan." [0:07–0:14] GUARDAR Y COMPARTIR ✂️: "Guárdalo y compártelo con alguien que siente que ya no encaja en su propia vida." [0:14–0:26] DOLOR: "Tienes lo que se supone que querías, y aun así sientes un vacío. Nadie a tu alrededor lo entiende, y empiezas a pensar que algo está mal contigo." [0:26–0:38] LISTA DE 3 ✂️: "Estas son las 3 señales: 1. Lo que antes te llenaba ahora te aburre. 2. Ya no aguantas conversaciones vacías. 3. Sientes que «tiene que haber algo más»." [0:38–0:57] DATO / AUTORIDAD: "Viktor Frankl, el psiquiatra que sobrevivió a los campos de concentración, llamó «vacío existencial» a esta sensación, y escribió que el ser humano puede soportar casi cualquier cosa si encuentra un para qué. Las tradiciones espirituales lo llaman la noche oscura del alma." [0:57–1:17] TU HISTORIA: "[TU HISTORIA REAL, 15–20 s: el momento en que sentiste que tu vida ya no te quedaba]" [1:17–1:55] HACKEO (hazlo conmigo) ✂️: "Escribe 3 momentos de tu vida en los que te sentiste viva de verdad. Luego busca qué tienen en común. Ahí está la primera pista de tu para qué. Repite conmigo: mi vacío es espacio para lo nuevo. Mi vacío es espacio para lo nuevo. Mi vacío es espacio para lo nuevo." [1:55–2:02] REVELACIÓN: "El vacío no es el final. Es el espacio donde empieza lo que de verdad eres." [2:02–2:04] COMENTA ✂️: "Si te pasa, comenta DESPERTANDO." [2:04–2:07] CTA: "Sígueme para más hackeos de consciencia." | K11: TikTok ≈ 2:07 min Reels/Shorts ≈ 1:06 min | L11: Video vertical 9:16, cara a cámara. TikTok: versión completa. Reels y Shorts: corte con las partes ✂️. Pon el TÍTULO DEL REEL como texto grande en pantalla los primeros 3 s y como portada. | M11: DESPERTANDO | N11: Sin venta (conexión) | O11: ¿Y si no estás perdida, sino despertando? 🌀 3 señales (y lo que dijo Viktor Frankl sobre ese vacío). Comenta DESPERTANDO 👇 #mabradiante #despertardeconciencia #espiritualidad #salirdelamatrix #mty | P11: 3 señales de que estás despertando #mabradiante #despertardeconciencia #espiritualidad #salirdelamatrix #mty #shorts | Q11: #mabradiante #despertardeconciencia #espiritualidad #salirdelamatrix #mty | R11: Meta: superar tu mediana de TikTok (11,850 vistas). Viral para ti: más de 17,775 (1.5x). Instagram, Facebook y YouTube: s/d, los medimos en la rutina semanal. | S11: P1 + P5 + P7 · Creencia + lista + autor | T11: Pieza 1 abre el tema del día con una creencia rota + lista de 3 señales (el combo que más rinde según tu competencia). Mediodía: tus TikToks de 10 a 13 h rinden 1.6x tu mediana (5 videos). | U11: Primera frase = gancho (G1, G2, G6 o G9), sin saludo: 2 Quita la culpa antes de enseñar: 1 Un dato de ciencia o un ejemplo real (hallazgo 2): 1 Algo para usar ya (hallazgo 1): 2 Pide guardar/compartir en los primeros 15 s: 1 Pide comentar una palabra: 1 Venta al final en 1 frase (o sin venta): 1 Vocabulario BNQ™, nada de la lista prohibida: 1 Total: 10/10 Lista de 3 (hallazgo 2): sí | V11: 10/10 | W11: Sin venta. Si la tristeza es constante o hay ideas de no vivir: Línea de la Vida 800 911 2000.
A12: Jueves | B12: 2026-10-15 | C12: 18:30 | D12: JUE-2 | E12: RITUAL DE 3 MINUTOS PARA VOLVER A TI | F12: TikTok · Instagram Reels · Facebook Reels · YouTube Shorts | G12: Vacío · desconexión de mí | H12: G2 · Promesa práctica («Cuidado con este video…») | I12: Alivio: «algo que puedo hacer ya» | J12: [0:00–0:07] GANCHO ✂️: "Cuidado con este video: este ritual de 3 minutos te devuelve a ti cuando te sientes vacía." [0:07–0:13] GUARDAR Y COMPARTIR ✂️: "Guárdalo para mañana temprano y compártelo con alguien que anda en piloto automático." [0:13–0:23] DOLOR: "Te levantas, agarras el celular, y el día se te va sin que te hayas preguntado ni una vez cómo estás tú." [0:23–0:33] LISTA DE 3 ✂️: "Son 3 pasos: 1. Mano en el corazón y 3 respiraciones lentas. 2. Pregúntate: ¿qué necesito hoy? 3. Di el decreto 3 veces." [0:33–0:48] DATO / AUTORIDAD: "La ciencia llama «interocepción» a tu capacidad de sentir lo que pasa dentro de tu cuerpo, y la investigación la relaciona con regular mejor tus emociones. Lo espiritual lo llama volver a tu centro." [0:48–1:24] HACKEO (hazlo conmigo) ✂️: "Hagámoslo ahora. Mano en el corazón. Respira lento… una… dos… tres. Pregúntate en silencio: ¿qué necesito hoy? Escucha lo primero que llegue. Ahora repite conmigo: estoy aquí, estoy despierta, elijo mi camino. Estoy aquí, estoy despierta, elijo mi camino. Estoy aquí, estoy despierta, elijo mi camino. Hecho está." [1:24–1:31] REVELACIÓN: "No necesitas irte a una montaña para encontrarte. Necesitas 3 minutos en los que no te abandones." [1:31–1:33] COMENTA ✂️: "Cuando lo hagas, comenta PRESENTE." [1:33–1:36] CTA: "Guárdalo y hazlo 7 mañanas seguidas." | K12: TikTok ≈ 1:36 min Reels/Shorts ≈ 1:01 min | L12: Video vertical 9:16, cara a cámara. TikTok: versión completa. Reels y Shorts: corte con las partes ✂️. Pon el TÍTULO DEL REEL como texto grande en pantalla los primeros 3 s y como portada. | M12: PRESENTE | N12: Sin venta (conexión) | O12: Ritual de 3 minutos para volver a ti 🤍 Para los días en que te sientes vacía o en piloto automático. Guárdalo y comenta PRESENTE 👇 #mabradiante #despertardeconciencia #espiritualidad #salirdelamatrix #mty | P12: Ritual de 3 minutos para volver a ti #mabradiante #despertardeconciencia #espiritualidad #salirdelamatrix #mty #shorts | Q12: #mabradiante #despertardeconciencia #espiritualidad #salirdelamatrix #mty | R12: Meta: superar tu mediana de TikTok (11,850 vistas). Viral para ti: más de 17,775 (1.5x). Instagram, Facebook y YouTube: s/d, los medimos en la rutina semanal. | S12: P2 · Herramienta para usar ya | T12: Pieza 2 es la herramienta para usar ya: el patrón #1 de tu competencia (26x) y el de tus 4 videos más vistos. Va en tu mejor horario: de 18 a 21 h tus TikToks rinden 6.3x tu mediana (7 videos). | U12: Primera frase = gancho (G1, G2, G6 o G9), sin saludo: 2 Quita la culpa antes de enseñar: 0 Un dato de ciencia o un ejemplo real (hallazgo 2): 1 Algo para usar ya (hallazgo 1): 2 Pide guardar/compartir en los primeros 15 s: 1 Pide comentar una palabra: 1 Venta al final en 1 frase (o sin venta): 1 Vocabulario BNQ™, nada de la lista prohibida: 1 Total: 9/10 Lista de 3 (hallazgo 2): sí | V12: 9/10 | W12: Herramienta para usar ya (H1).
A13: Jueves | B13: 2026-10-15 | C13: 20:30 | D13: JUE-3 | E13: LO QUE STEVE JOBS DIJO SOBRE UNIR LOS PUNTOS | F13: TikTok · Instagram Reels · Facebook Reels · YouTube Shorts | G13: Vacío · no le encuentro sentido | H13: G9 · Ejemplo famoso + lista | I13: Inspiración: «esto tiene sentido» | J13: [0:00–0:10] GANCHO ✂️: "En 2005, Steve Jobs dijo en la Universidad de Stanford una frase que explica por qué hoy no le encuentras sentido a tu vida." [0:10–0:15] GUARDAR Y COMPARTIR ✂️: "Guárdalo y compártelo con alguien que está en plena crisis de sentido." [0:15–0:26] DOLOR: "Miras tu vida y no entiendes para qué pasó lo que pasó: la ruptura, el trabajo que perdiste, la crisis que te obligó a parar." [0:26–0:48] LISTA DE 3 ✂️: "Jobs dijo que los puntos no se unen mirando hacia adelante, solo hacia atrás. Y hay 3 puntos que quizá ya estás uniendo: 1. La crisis que te obligó a parar. 2. La pregunta que no te deja en paz. 3. Lo que de pronto te encuentra, como este video." [0:48–1:03] DATO / AUTORIDAD: "Fue en su discurso de graduación de Stanford: «no puedes unir los puntos mirando hacia adelante; solo puedes unirlos mirando hacia atrás». Lo espiritual lo llama sincronicidad; la psicología, darle sentido a tu historia." [1:03–1:23] TU HISTORIA: "[TU HISTORIA REAL, 15–20 s: un momento difícil que hoy entiendes que te llevó a donde estás]" [1:23–1:59] HACKEO (hazlo conmigo) ✂️: "Dibuja una línea en una hoja. Pon 5 momentos clave de tu vida, buenos y difíciles. Únelos. Y pregúntate: ¿hacia dónde apuntan? Repite conmigo: nada de lo que viví fue en vano. Nada de lo que viví fue en vano. Nada de lo que viví fue en vano." [1:59–2:04] REVELACIÓN: "Tu vida no está desordenada. Todavía no has visto el dibujo completo." [2:04–2:10] COMENTA ✂️: "Si quieres un mapa para tu despertar, comenta DESPIERTA y te mando el link." [2:10–2:17] CTA: "En DESPIERTA te acompaño en los primeros pasos de tu despertar con un mapa claro." | K13: TikTok ≈ 2:17 min Reels/Shorts ≈ 1:19 min | L13: Video vertical 9:16, cara a cámara. TikTok: versión completa. Reels y Shorts: corte con las partes ✂️. Pon el TÍTULO DEL REEL como texto grande en pantalla los primeros 3 s y como portada. | M13: DESPIERTA | N13: DESPIERTA · $499 | O13: Lo que Steve Jobs dijo sobre unir los puntos 🔗 y por qué hoy no le encuentras sentido a tu vida. Comenta DESPIERTA y te mando el link 👇 #mabradiante #despertardeconciencia #espiritualidad #salirdelamatrix #mty | P13: Lo que Steve Jobs dijo sobre unir los puntos #mabradiante #despertardeconciencia #espiritualidad #salirdelamatrix #mty #shorts | Q13: #mabradiante #despertardeconciencia #espiritualidad #salirdelamatrix #mty | R13: Meta: superar tu mediana de TikTok (11,850 vistas). Viral para ti: más de 17,775 (1.5x). Instagram, Facebook y YouTube: s/d, los medimos en la rutina semanal. | S13: P7 + P5 · Famoso + lista de 3 | T13: Pieza 3 vende, apoyada en un famoso o estudio real (7.6x) + lista. Va al final del día, cuando ya calentaste el tema. Sigue en tu mejor franja. | U13: Primera frase = gancho (G1, G2, G6 o G9), sin saludo: 2 Quita la culpa antes de enseñar: 0 Un dato de ciencia o un ejemplo real (hallazgo 2): 1 Algo para usar ya (hallazgo 1): 2 Pide guardar/compartir en los primeros 15 s: 1 Pide comentar una palabra: 1 Venta al final en 1 frase (o sin venta): 1 Vocabulario BNQ™, nada de la lista prohibida: 1 Total: 9/10 Lista de 3 (hallazgo 2): sí | V13: 9/10 | W13: Pieza de venta del día (1 de 3).
... A22: Domingo | B22: 2026-10-18 | C22: 20:30 | D22: DOM-3 | E22: LLAVE DE LUZ: ABRE TU SEMANA CON ESTE DECRETO | F22: TikTok · Instagram Reels · Facebook Reels · YouTube Shorts | G22: Valor · decreto de inicio de semana | H22: G2 · Promesa práctica («Cuidado con este video…») | I22: Alivio + esperanza | J22: [0:00–0:06] GANCHO ✂️: "Cuidado con este video: este decreto abre tu semana antes de que empiece." [0:06–0:11] GUARDAR Y COMPARTIR ✂️: "Guárdalo y compártelo con alguien que quiere empezar la semana diferente." [0:11–0:18] DOLOR: "El domingo en la noche te llega esa sensación en el estómago: otra semana igual." [0:18–0:28] LISTA DE 3 ✂️: "Son 3 pasos: 1. Escribe 3 intenciones para tu semana. 2. Mano en el pecho y respira lento. 3. Di el decreto 3 veces." [0:28–0:45] DATO / AUTORIDAD: "«Llave de luz» es una de mis palabras gatillo: frases cortas que se repiten 3 veces para anclar una intención. Es un ritual, no ciencia: su fuerza está en la repetición y en la intención con que lo dices." [0:45–1:23] HACKEO (hazlo conmigo) ✂️: "Escribe tus 3 intenciones. Mano en el pecho. Respira lento. Ahora repite conmigo: abro mi semana a lo que sí elijo. Abro mi semana a lo que sí elijo. Abro mi semana a lo que sí elijo. Llave de luz, llave de luz, llave de luz. Hecho está, hecho está, hecho está." [1:23–1:29] REVELACIÓN: "Tu semana no empieza el lunes. Empieza cuando decides cómo la vas a vivir." [1:29–1:32] COMENTA ✂️: "Cuando lo hagas, comenta HECHO ESTÁ." [1:32–1:34] CTA: "Guárdalo y hazlo cada domingo." | K22: TikTok ≈ 1:34 min Reels/Shorts ≈ 1:02 min | L22: Video vertical 9:16, cara a cámara. TikTok: versión completa. Reels y Shorts: corte con las partes ✂️. Pon el TÍTULO DEL REEL como texto grande en pantalla los primeros 3 s y como portada. | M22: HECHO ESTÁ | N22: Sin venta (conexión) | O22: Llave de luz 🗝️✨ Abre tu semana con este decreto antes de que empiece. Guárdalo y comenta HECHO ESTÁ 👇 #mabradiante #hackeatumente #espiritualidad #decreto #mty | P22: Llave de luz: abre tu semana con este decreto #mabradiante #hackeatumente #espiritualidad #decreto #mty #shorts | Q22: #mabradiante #hackeatumente #espiritualidad #decreto #mty | R22: Meta: superar tu mediana de TikTok (11,850 vistas). Viral para ti: más de 17,775 (1.5x). Instagram, Facebook y YouTube: s/d, los medimos en la rutina semanal. | S22: P2 · Herramienta para usar ya | T22: Pieza 3 vende, apoyada en un famoso o estudio real (7.6x) + lista. Va al final del día, cuando ya calentaste el tema. Sigue en tu mejor franja. | U22: Primera frase = gancho (G1, G2, G6 o G9), sin saludo: 2 Quita la culpa antes de enseñar: 0 Un dato de ciencia o un ejemplo real (hallazgo 2): 1 Algo para usar ya (hallazgo 1): 2 Pide guardar/compartir en los primeros 15 s: 1 Pide comentar una palabra: 1 Venta al final en 1 frase (o sin venta): 1 Vocabulario BNQ™, nada de la lista prohibida: 1 Total: 9/10 Lista de 3 (hallazgo 2): sí | V22: 9/10 | W22: Sin venta. Mismo formato que tu video viral de 2.2M (decreto + «hecho está»).
W24: Grabadas: | X24: =COUNTIF(X2:X22,"Sí")&" de "&COUNTA(D2:D22)
W25: Publicadas: | X25: =COUNTIF(Y2:Y22,"Sí")&" de "&COUNTA(D2:D22)

Sheet Guion por partes
A1: PIEZA | B1: TÍTULO DEL REEL | C1: GANCHO | D1: GUARDAR Y COMPARTIR | E1: DOLOR | F1: LISTA DE 3 | G1: DATO / AUTORIDAD | H1: TU HISTORIA (real) | I1: HACKEO | J1: REVELACIÓN | K1: COMENTA | L1: CTA
A2: LUN-1 | B2: 3 SEÑALES DE QUE TU MENTE RECHAZA EL DINERO | C2: No es que no te alcance el dinero. Es que tu mente tiene 3 programas que lo sacan de tu vida, y casi nadie los ve. | D2: Guarda este video antes de que se te pierda y compártelo con alguien que siente que el dinero se le escapa de las manos. | E2: Te pagan y a la semana ya no hay. Te llega un dinero extra y justo aparece un gasto del mismo tamaño. Y empiezas a creer que el dinero no es para ti. No eres tú. Es un programa que se instaló antes de que pudieras elegirlo. | F2: Estas son las 3 señales: 1. Cuando te llega dinero sientes alivio… y luego culpa o miedo a perderlo. 2. Te cuesta cobrar lo que vale tu trabajo, y pedir más te da vergüenza. 3. En tu casa, hablar de dinero era sinónimo de pelea o de «no alcanza». | G2: Los investigadores Sendhil Mullainathan y Eldar Shafir lo explican en su libro «Escasez»: cuando la mente vive en carencia, le queda menos espacio para pensar y decidir. No es falta de inteligencia: es una mente ocupada sobreviviendo. Desde lo energético, es una frecuencia de «no alcanza» que se repite hasta que la ves. | H2: [TU HISTORIA REAL, 15–20 s: la frase de dinero que más escuchaste de niña y cómo se repitió en tu vida] | I2: Esta noche toma una hoja. Arriba escribe la frase de dinero que más escuchaste de niña. Abajo escribe su versión nueva. Por ejemplo: «no alcanza» se convierte en «el dinero llega y yo sé sostenerlo». Léela en voz alta 3 veces antes de dormir, durante 7 noches. Repite conmigo: el dinero llega y yo sé sostenerlo. El dinero llega y yo sé sostenerlo. El dinero llega y yo sé sostenerlo. | J2: El dinero no se va porque seas mala con él. Se va porque tu cuerpo todavía no se siente seguro teniéndolo. | K2: Comenta SEÑALES y dime cuál de las 3 es la tuya. | L2: Sígueme: esta semana te traigo un hackeo para cada área de tu vida.
A3: LUN-2 | B3: DI ESTO CADA VEZ QUE PAGUES ALGO | C3: Cuidado con este video porque vamos a cambiar la forma en que tu cuerpo recibe y suelta el dinero. | D3: Guárdalo antes de que se te pierda y compártelo con la amiga que siempre dice «no me alcanza». | E3: Abres la app del banco y se te aprieta el estómago. Pagas algo y sientes que pierdes. Eso no es tacañería: es tu sistema nervioso asociando dinero con peligro. | F3: Lo vamos a hacer en 3 pasos: 1. Antes de pagar, pon la mano en el pecho y exhala largo. 2. Mira el dinero o la pantalla y di el decreto. 3. Sonríe al pagar, aunque al principio te cueste. | G3: Tu cerebro aprende por repetición: cada vez que repites una sensación, esa conexión neuronal se fortalece. Por eso este ritual se hace 3 veces y durante 7 días. Lo espiritual lo llama decreto; la neurociencia, neuroplasticidad. | H3: — | I3: Hagámoslo juntas ahora. Mano en el pecho. Inhala… y exhala largo. Ahora repite conmigo: gracias por llegar, te recibo con calma, te dejo ir sabiendo que regresas multiplicado. Otra vez: gracias por llegar, te recibo con calma, te dejo ir sabiendo que regresas multiplicado. Una más: gracias por llegar, te recibo con calma, te dejo ir sabiendo que regresas multiplicado. Tarro de miel, tarro de miel, tarro de miel. | J3: No necesitas más dinero para estar en paz con él. Necesitas paz para que el dinero se quede. | K3: Cuando lo hagas, comenta HECHO ESTÁ. | L3: Guárdalo y hazlo 7 días seguidos.
A4: LUN-3 | B4: EL CHEQUE DE 10 MILLONES DE JIM CARREY | C4: Jim Carrey se escribió un cheque de 10 millones de dólares cuando todavía no tenía éxito. Y lo que hizo después es lo que casi nadie cuenta. | D4: Guárdalo y compártelo con alguien que ya hizo su vision board y sigue esperando. | E4: Tú también has escrito metas, has visualizado, has hecho rituales… y nada. Y empiezas a preguntarte qué te falta. | F4: Lo que hizo Carrey tiene 3 partes, y si te falta una, tu visualización se queda en sueño: 1. Una cifra y una fecha concretas: él puso 10 millones y Acción de Gracias de 1995. 2. Sentirlo en el cuerpo, no solo pensarlo: él lo cargaba en la cartera y lo veía cada día. 3. Actuar cada día como la persona que ya lo tiene: él mismo dice que no basta con visualizar y sentarse a esperar. | G4: Carrey contó en entrevistas que a principios de los 90 se escribió ese cheque «por servicios de actuación prestados». Poco antes de esa fecha supo que le pagarían 10 millones por una película. Lo espiritual lo llama decretar; la psicología lo llama identidad: actúas según quien crees que eres. | H4: [TU HISTORIA REAL, 15–20 s: una meta que se te dio cuando empezaste a actuar como si ya la tuvieras] | I4: Hoy escribe tu propio cheque: tu nombre, una cifra realista para los próximos 12 meses y una fecha. Detrás escribe: ¿qué haría hoy la mujer que ya cobra esto? Y haz una de esas cosas hoy mismo. Repite conmigo: soy la mujer que ya lo recibe. Soy la mujer que ya lo recibe. Soy la mujer que ya lo recibe. | J4: El cheque no trae el dinero. Te cambia a ti, y tú traes el dinero. | K4: Si quieres que te guíe, comenta ADN y te mando el link. | L4: En ADN Millonario trabajamos los programas de dinero que heredaste para activar tu frecuencia de abundancia.
A5: MAR-1 | B5: 3 SEÑALES DE ANSIEDAD QUE CREES QUE SON TU PERSONALIDAD | C5: No eres intensa ni exagerada. Hay 3 señales de ansiedad que la mayoría confunde con su forma de ser. | D5: Guárdalo y compártelo con alguien a quien siempre le dicen «relájate». | E5: Por fuera estás bien, por dentro vas corriendo. Te dicen «relájate» y te dan ganas de llorar. No es que seas así. Es que tu cuerpo aprendió a vivir en alerta. | F5: Estas son las 3 señales: 1. Necesitas tener todo bajo control, y un cambio de planes te desarma. 2. Imaginas la peor versión de todo «para estar preparada». 3. Te cuesta descansar sin sentir culpa. | G5: La ciencia lo explica así: cuando el cerebro se acostumbra a estar en alerta, la amígdala, tu detector de peligro, se activa con más facilidad, y el cuerpo vive como si algo malo estuviera por pasar. Las tradiciones contemplativas lo llaman una mente que no está en el presente. | H5: [TU HISTORIA REAL, 15–20 s: cómo se veía tu ansiedad con TDAH antes de aprender a dirigir tu mente] | I5: Cuando notes una de estas 3 señales, ponle nombre en voz baja: «esto es mi alarma, no la realidad». Luego pregúntate: ¿qué es lo que sí está pasando ahora mismo? Repite conmigo: esto es mi alarma, no la realidad. Esto es mi alarma, no la realidad. Esto es mi alarma, no la realidad. | J5: Tú no eres ansiosa. Tienes una alarma que nadie te enseñó a apagar. | K5: Comenta ALARMA y dime cuál de las 3 te pasa más. | L5: Sígueme para más hackeos para tu mente.
A6: MAR-2 | B6: EL SUSPIRO QUE BAJA LA ANSIEDAD EN 1 MINUTO | C6: Haz esto conmigo ahora mismo y siente cómo baja la ansiedad en menos de un minuto. | D6: Guárdalo para cuando lo necesites y compártelo con alguien que hoy trae el pecho apretado. | E6: Ese nudo en el pecho, el corazón rápido, la mente que no para. Y todos te dicen «respira»… pero nadie te dice cómo. | F6: Se llama suspiro cíclico y son 3 pasos: 1. Inhala por la nariz. 2. Encima, una segunda inhalación cortita, hasta llenarte. 3. Exhala largo y lento por la boca. | G6: En 2023, un estudio de la Universidad de Stanford, publicado en Cell Reports Medicine, comparó varias técnicas de respiración. Las personas que hicieron este suspiro 5 minutos al día mejoraron más su estado de ánimo que las que hicieron meditación de atención. La exhalación larga le avisa a tu cuerpo que no hay peligro. | H6: — | I6: Hagámoslo juntas. Inhala por la nariz… otra inhalación cortita encima… y exhala largo por la boca. Otra vez: inhala… otra cortita… exhala largo. Una vez más: inhala… cortita… y suelta todo. Ahora repite conmigo: estoy a salvo. Estoy a salvo. Estoy a salvo. Hielo azul, hielo azul, hielo azul. | J6: Tu respiración es el control remoto de tu sistema nervioso, y lo traes contigo a todas partes. | K6: Si sentiste la diferencia, comenta CALMA. | L6: Guárdalo y hazlo 5 minutos al día esta semana.
A7: MAR-3 | B7: 15 MINUTOS DE ESCRITURA QUE CALMAN TU MENTE | C7: Un psicólogo de Texas descubrió que escribir 15 minutos lo que sientes puede bajar tu carga mental. Y casi nadie lo usa. | D7: Guárdalo y compártelo con alguien que se acuesta y su mente se prende. | E7: Te acuestas, apagas la luz… y tu mente empieza a repasar todo lo que dijiste, lo que falta y lo que podría salir mal. | F7: Tu mente no suelta por 3 errores muy comunes: 1. Intentas no pensar, y piensas más. 2. Te llevas los pendientes a la cama. 3. Te callas lo que sientes para no molestar. | G7: James Pennebaker, de la Universidad de Texas, estudió la «escritura expresiva»: personas que escribieron de 15 a 20 minutos sobre lo que sentían, durante unos días, reportaron sentirse mejor que las que escribieron de temas neutros. Desde lo energético: lo que no se expresa se queda dando vueltas en tu campo. | H7: [TU HISTORIA REAL, 15–20 s: qué hacías tú en las noches cuando tu mente no te dejaba dormir] | I7: Hoy, antes de dormir: 10 minutos escribiendo sin parar lo que sientes, no lo que tienes que hacer. No corrijas nada. Cuando termines, cierra la libreta y di: lo solté en el papel, ya no lo cargo en el cuerpo. Repite conmigo: lo solté en el papel, ya no lo cargo en el cuerpo. Lo solté en el papel, ya no lo cargo en el cuerpo. | J7: Lo que no se expresa se queda dando vueltas. Lo que escribes deja de cargarte. | K7: Si tu mente no te deja dormir, comenta DORMIR y te mando el link. | L7: En Querida Ansiedad te doy la auditoría mental y los audios para bajarle la velocidad a tu mente.
A8: MIÉ-1 | B8: 3 SEÑALES DE QUE NO ES AMOR, ES ENGANCHE | C8: No es que lo ames demasiado. Es que tu cerebro está enganchado, y hay 3 señales que lo delatan. | D8: Guárdalo y compártelo con esa amiga que siempre vuelve con la misma persona. | E8: Revisas si se conectó. Ves sus historias aunque te duelan. Te prometes no escribirle… y le escribes. No estás loca. Estás enganchada. | F8: Estas son las 3 señales: 1. Te sientes peor cuando lo ves, pero no puedes dejar de buscarlo. 2. Un mensaje suyo te sube al cielo y su silencio te tira al piso. 3. Ya sabes que no te hace bien… y aun así lo justificas. | G8: El psicólogo B. F. Skinner observó que cuando una recompensa llega a veces sí y a veces no, la conducta se vuelve más difícil de soltar. Es lo mismo que pasa con las máquinas tragamonedas. Por eso una relación intermitente engancha más que una estable. En lo energético, es un cordón que sigue abierto. | H8: [TU HISTORIA REAL, 15–20 s: una relación en la que confundiste intensidad con amor] | I8: Esta semana, cada vez que quieras revisar su perfil, cuenta hasta 10 y di en voz baja: esto es enganche, no amor; mi atención es mía. Repite conmigo: esto es enganche, no amor; mi atención es mía. Esto es enganche, no amor; mi atención es mía. Esto es enganche, no amor; mi atención es mía. | J8: El enganche se siente como amor porque es intenso. El amor sano se siente como paz. | K8: Comenta ENGANCHE si te pasó o te está pasando. | L8: Sígueme: estoy preparando algo para ayudarte a soltar.
A9: MIÉ-2 | B9: CORTA EL CORDÓN CON ESTE DECRETO | C9: Cuidado con este video si no puedes dejar de pensar en alguien que ya se fue. | D9: Guárdalo para la noche en que más lo necesites y compártelo con quien está soltando a alguien. | E9: Ya terminó, pero sigues sintiéndolo. Piensas en él justo cuando él publica algo. Es como si hubiera un cable que nunca se desconectó. | F9: El ritual tiene 3 pasos: 1. Cierra los ojos e imagínalo frente a ti. 2. Observa el cordón de luz que los une. 3. Córtalo con amor, sin rabia, con el decreto. | G9: En muchas tradiciones espirituales se habla de cordones energéticos: los lazos que quedan después de una relación. No es ciencia, es un ritual, y los rituales le dan al cuerpo un cierre que la mente sola no encuentra. | H9: — | I9: Hagámoslo ahora. Cierra los ojos. Imagínalo frente a ti. Mira el cordón que los une. Ahora, en tu mano aparece una espada de luz. Repite conmigo: te devuelvo lo que es tuyo, recupero lo que es mío. Te devuelvo lo que es tuyo, recupero lo que es mío. Te devuelvo lo que es tuyo, recupero lo que es mío. Espada de luz, espada de luz, espada de luz. Corta. Respira. Hecho está. | J9: Soltar no es olvidarlo. Es dejar de darle tu energía. | K9: Cuando lo hagas, comenta LIBRE. | L9: Guárdalo para cuando lo necesites.
